<?xml version="1.0"?>
<robot xmlns:xacro="http://www.ros.org/wiki/xacro">

  <xacro:macro name="mobile_base" params="prefix">

    <!-- Base Link -->
    <link name="${prefix}base_footprint"/>

    <joint name="${prefix}base_joint" type="fixed">
      <parent link="${prefix}base_footprint"/>
      <child link="${prefix}base_link"/>
      <origin xyz="0 0 0.1" rpy="0 0 0"/>
    </joint>

    <link name="${prefix}base_link">
      <visual>
        <origin xyz="0 0 0" rpy="0 0 0"/>
        <geometry>
          <cylinder radius="0.25" length="0.1"/>
        </geometry>
        <material name="blue"/>
      </visual>
      <collision>
        <origin xyz="0 0 0" rpy="0 0 0"/>
        <geometry>
          <cylinder radius="0.25" length="0.1"/>
        </geometry>
      </collision>
    </link>

    <!-- Wheels -->
    <xacro:macro name="wheel" params="prefix side y_pos">
      <joint name="${prefix}${side}_wheel_joint" type="continuous">
        <parent link="${prefix}base_link"/>
        <child link="${prefix}${side}_wheel_link"/>
        <origin xyz="0 ${y_pos} 0" rpy="-${PI/2} 0 0"/>
        <axis xyz="0 0 1"/>
      </joint>

      <link name="${prefix}${side}_wheel_link">
        <visual>
          <geometry>
            <cylinder radius="0.1" length="0.05"/>
          </geometry>
          <material name="black"/>
        </visual>
        <collision>
          <geometry>
            <cylinder radius="0.1" length="0.05"/>
          </geometry>
        </collision>
      </link>
    </xacro:macro>

    <xacro:wheel prefix="${prefix}" side="left" y_pos="0.25"/>
    <xacro:wheel prefix="${prefix}" side="right" y_pos="-0.25"/>

    <!-- Caster Wheels -->
    <xacro:macro name="caster_wheel" params="prefix x_pos">
        <joint name="${prefix}caster_${x_pos}_joint" type="fixed">
            <parent link="${prefix}base_link"/>
            <child link="${prefix}caster_${x_pos}_link"/>
            <origin xyz="${x_pos} 0 -0.05" rpy="0 0 0"/>
        </joint>

        <link name="${prefix}caster_${x_pos}_link">
            <visual>
                <geometry>
                    <sphere radius="0.05"/>
                </geometry>
                <material name="black"/>
            </visual>
            <collision>
                <geometry>
                    <sphere radius="0.05"/>
                </geometry>
            </collision>
        </link>
    </xacro:macro>

    <xacro:caster_wheel prefix="${prefix}" x_pos="0.15"/>
    <xacro:caster_wheel prefix="${prefix}" x_pos="-0.15"/>

  </xacro:macro>
</robot>