<?xml version="1.0"?>
<robot xmlns:xacro="http://www.ros.org/wiki/xacro">

  <xacro:macro name="mobile_base" params="prefix">
    <link name="${prefix}base_footprint"/>
    <joint name="${prefix}base_joint" type="fixed">
      <parent link="${prefix}base_footprint"/>
      <child link="${prefix}base_link"/>
      <origin xyz="0 0 0.1" rpy="0 0 0"/>
    </joint>
    <link name="${prefix}base_link">
      <visual><geometry><cylinder radius="0.25" length="0.1"/></geometry><material name="blue"/></visual>
      <collision><geometry><cylinder radius="0.25" length="0.1"/></geometry></collision>
      <inertial><mass value="5.0"/><inertia ixx="0.1" ixy="0" ixz="0" iyy="0.1" iyz="0" izz="0.1"/></inertial>
    </link>

    <xacro:macro name="wheel" params="side y_pos">
      <joint name="${prefix}${side}_wheel_joint" type="continuous"><parent link="${prefix}base_link"/><child link="${prefix}${side}_wheel_link"/><origin xyz="0 ${y_pos} 0" rpy="-${PI/2} 0 0"/><axis xyz="0 0 1"/></joint>
      <link name="${prefix}${side}_wheel_link">
        <visual><geometry><cylinder radius="0.1" length="0.05"/></geometry><material name="black"/></visual>
        <collision><geometry><cylinder radius="0.1" length="0.05"/></geometry></collision>
        <inertial><mass value="0.5"/><inertia ixx="0.01" ixy="0" ixz="0" iyy="0.01" iyz="0" izz="0.01"/></inertial>
      </link>
    </xacro:macro>
    <xacro:wheel side="left" y_pos="0.255"/>
    <xacro:wheel side="right" y_pos="-0.255"/>

    <xacro:macro name="caster_wheel" params="x_pos">
        <joint name="${prefix}caster_${x_pos}_joint" type="fixed"><parent link="${prefix}base_link"/><child link="${prefix}caster_${x_pos}_link"/><origin xyz="${x_pos} 0 -0.05" rpy="0 0 0"/></joint>
        <link name="${prefix}caster_${x_pos}_link">
            <visual><geometry><sphere radius="0.05"/></geometry><material name="black"/></visual>
            <collision><geometry><sphere radius="0.05"/></geometry></collision>
            <inertial><mass value="0.2"/><inertia ixx="0.001" ixy="0" ixz="0" iyy="0.001" iyz="0" izz="0.001"/></inertial>
        </link>
    </xacro:macro>
    <xacro:caster_wheel x_pos="0.15"/>
    <xacro:caster_wheel x_pos="-0.15"/>
  </xacro:macro>
</robot>