<?xml version="1.0"?>
<robot name="debug_bot" xmlns:xacro="http://www.ros.org/wiki/xacro">

    <xacro:property name="PI" value="3.1415926535897931"/>
    <link name="base_footprint"/>
    <joint name="base_joint" type="fixed">
      <parent link="base_footprint"/>
      <child link="base_link"/>
      <origin xyz="0 0 0.1" rpy="0 0 0"/>
    </joint>
    <link name="base_link">
      <visual><geometry><cylinder radius="0.25" length="0.1"/></geometry><material name="blue"><color rgba="0.0 0.0 0.8 1.0"/></material></visual>
      <collision><geometry><cylinder radius="0.25" length="0.1"/></geometry></collision>
      <inertial><mass value="5.0"/><inertia ixx="0.1" ixy="0" ixz="0" iyy="0.1" iyz="0" izz="0.1"/></inertial>
    </link>
    <xacro:macro name="wheel" params="prefix side y_pos">
      <joint name="${prefix}${side}_wheel_joint" type="continuous"><parent link="base_link"/><child link="${prefix}${side}_wheel_link"/><origin xyz="0 ${y_pos} 0" rpy="-${PI/2} 0 0"/><axis xyz="0 0 1"/></joint>
      <link name="${prefix}${side}_wheel_link">
        <visual><geometry><cylinder radius="0.1" length="0.05"/></geometry><material name="black"><color rgba="0.1 0.1 0.1 1.0"/></material></visual>
        <collision><geometry><cylinder radius="0.1" length="0.05"/></geometry></collision>
        <inertial><mass value="0.5"/><inertia ixx="0.01" ixy="0" ixz="0" iyy="0.01" iyz="0" izz="0.01"/></inertial>
      </link>
    </xacro:macro>
    <xacro:wheel prefix="" side="left" y_pos="0.255"/>
    <xacro:wheel prefix="" side="right" y_pos="-0.255"/>
    <xacro:macro name="caster_wheel" params="prefix x_pos">
        <joint name="${prefix}caster_${x_pos}_joint" type="fixed"><parent link="base_link"/><child link="${prefix}caster_${x_pos}_link"/><origin xyz="${x_pos} 0 -0.05" rpy="0 0 0"/></joint>
        <link name="${prefix}caster_${x_pos}_link">
            <visual><geometry><sphere radius="0.05"/></geometry><material name="black"><color rgba="0.1 0.1 0.1 1.0"/></material></visual>
            <collision><geometry><sphere radius="0.05"/></geometry></collision>
            <inertial><mass value="0.2"/><inertia ixx="0.001" ixy="0" ixz="0" iyy="0.001" iyz="0" izz="0.001"/></inertial>
        </link>
    </xacro:macro>
    <xacro:caster_wheel prefix="" x_pos="0.15"/>
    <xacro:caster_wheel prefix="" x_pos="-0.15"/>
</robot>