<?xml version="1.0"?>
<robot name="foundry_bot">

  <material name="blue"><color rgba="0.0 0.0 0.8 1.0"/></material>
  <material name="black"><color rgba="0.0 0.0 0.0 1.0"/></material>
  <material name="grey"><color rgba="0.5 0.5 0.5 1.0"/></material>

  <link name="base_footprint"/>
  <joint name="base_joint" type="fixed">
    <parent link="base_footprint"/>
    <child link="base_link"/>
    <origin xyz="0 0 0.1" rpy="0 0 0"/>
  </joint>
  <link name="base_link">
    <visual><geometry><cylinder radius="0.25" length="0.1"/></geometry><material name="blue"/></visual>
    <collision><geometry><cylinder radius="0.25" length="0.1"/></geometry></collision>
    <inertial><mass value="5.0"/><inertia ixx="0.1" ixy="0" ixz="0" iyy="0.1" iyz="0" izz="0.1"/></inertial>
  </link>
  <joint name="left_wheel_joint" type="continuous">
    <parent link="base_link"/><child link="left_wheel_link"/><origin xyz="0 0.255 0" rpy="-1.57079632679 0 0"/><axis xyz="0 0 1"/>
  </joint>
  <link name="left_wheel_link">
    <visual><geometry><cylinder radius="0.1" length="0.05"/></geometry><material name="black"/></visual>
    <collision><geometry><cylinder radius="0.1" length="0.05"/></geometry></collision>
    <inertial><mass value="0.5"/><inertia ixx="0.01" ixy="0" ixz="0" iyy="0.01" iyz="0" izz="0.01"/></inertial>
  </link>
  <joint name="right_wheel_joint" type="continuous">
    <parent link="base_link"/><child link="right_wheel_link"/><origin xyz="0 -0.255 0" rpy="-1.57079632679 0 0"/><axis xyz="0 0 1"/>
  </joint>
  <link name="right_wheel_link">
    <visual><geometry><cylinder radius="0.1" length="0.05"/></geometry><material name="black"/></visual>
    <collision><geometry><cylinder radius="0.1" length="0.05"/></geometry></collision>
    <inertial><mass value="0.5"/><inertia ixx="0.01" ixy="0" ixz="0" iyy="0.01" iyz="0" izz="0.01"/></inertial>
  </link>
  <joint name="caster_0.15_joint" type="fixed">
    <parent link="base_link"/><child link="caster_0.15_link"/><origin xyz="0.15 0 -0.05" rpy="0 0 0"/>
  </joint>
  <link name="caster_0.15_link">
    <visual><geometry><sphere radius="0.05"/></geometry><material name="black"/></visual>
    <collision><geometry><sphere radius="0.05"/></geometry></collision>
    <inertial><mass value="0.2"/><inertia ixx="0.001" ixy="0" ixz="0" iyy="0.001" iyz="0" izz="0.001"/></inertial>
  </link>
  <joint name="caster_-0.15_joint" type="fixed">
    <parent link="base_link"/><child link="caster_-0.15_link"/><origin xyz="-0.15 0 -0.05" rpy="0 0 0"/>
  </joint>
  <link name="caster_-0.15_link">
    <visual><geometry><sphere radius="0.05"/></geometry><material name="black"/></visual>
    <collision><geometry><sphere radius="0.05"/></geometry></collision>
    <inertial><mass value="0.2"/><inertia ixx="0.001" ixy="0" ixz="0" iyy="0.001" iyz="0" izz="0.001"/></inertial>
  </link>

  <joint name="arm_base_joint" type="fixed"><parent link="base_link"/><child link="arm_base_link"/><origin xyz="0 0 0.05" rpy="0 0 0"/></joint>
  <link name="arm_base_link">
    <visual><geometry><cylinder radius="0.07" length="0.05"/></geometry><material name="grey"/></visual>
    <collision><geometry><cylinder radius="0.07" length="0.05"/></geometry></collision>
    <inertial><mass value="0.5"/><inertia ixx="0.01" ixy="0" ixz="0" iyy="0.01" iyz="0" izz="0.01"/></inertial>
  </link>
  <joint name="joint1" type="revolute"><parent link="arm_base_link"/><child link="link1"/><origin xyz="0 0 0.025" rpy="0 0 0"/><axis xyz="0 0 1"/><limit lower="-3.14159" upper="3.14159" effort="100" velocity="1.0"/></joint>
  <link name="link1">
    <visual><geometry><cylinder radius="0.05" length="0.2"/></geometry><origin xyz="0 0 0.1" rpy="0 0 0"/><material name="blue"/></visual>
    <collision><geometry><cylinder radius="0.05" length="0.2"/></geometry><origin xyz="0 0 0.1" rpy="0 0 0"/></collision>
    <inertial><mass value="1.0"/><inertia ixx="0.01" ixy="0" ixz="0" iyy="0.01" iyz="0" izz="0.01"/></inertial>
  </link>
  <joint name="joint2" type="revolute"><parent link="link1"/><child link="link2"/><origin xyz="0 0 0.2" rpy="0 0 0"/><axis xyz="0 1 0"/><limit lower="-1.57079" upper="1.57079" effort="100" velocity="1.0"/></joint>
  <link name="link2">
    <visual><geometry><cylinder radius="0.05" length="0.3"/></geometry><origin xyz="0 0 0.15" rpy="0 0 0"/><material name="blue"/></visual>
    <collision><geometry><cylinder radius="0.05" length="0.3"/></geometry><origin xyz="0 0 0.15" rpy="0 0 0"/></collision>
    <inertial><mass value="1.5"/><inertia ixx="0.01" ixy="0" ixz="0" iyy="0.01" iyz="0" izz="0.01"/></inertial>
  </link>
  <joint name="joint3" type="revolute"><parent link="link2"/><child link="link3"/><origin xyz="0 0 0.3" rpy="0 0 0"/><axis xyz="0 1 0"/><limit lower="-1.57079" upper="1.57079" effort="100" velocity="1.0"/></joint>
  <link name="link3">
    <visual><geometry><cylinder radius="0.05" length="0.25"/></geometry><origin xyz="0 0 0.125" rpy="0 0 0"/><material name="blue"/></visual>
    <collision><geometry><cylinder radius="0.05" length="0.25"/></geometry><origin xyz="0 0 0.125" rpy="0 0 0"/></collision>
    <inertial><mass value="1.2"/><inertia ixx="0.01" ixy="0" ixz="0" iyy="0.01" iyz="0" izz="0.01"/></inertial>
  </link>
  <joint name="joint4" type="revolute"><parent link="link3"/><child link="link4"/><origin xyz="0 0 0.25" rpy="0 0 0"/><axis xyz="1 0 0"/><limit lower="-3.14159" upper="3.14159" effort="100" velocity="1.0"/></joint>
  <link name="link4">
    <visual><geometry><cylinder radius="0.05" length="0.1"/></geometry><origin xyz="0 0 0.05" rpy="0 0 0"/><material name="blue"/></visual>
    <collision><geometry><cylinder radius="0.05" length="0.1"/></geometry><origin xyz="0 0 0.05" rpy="0 0 0"/></collision>
    <inertial><mass value="0.5"/><inertia ixx="0.01" ixy="0" ixz="0" iyy="0.01" iyz="0" izz="0.01"/></inertial>
  </link>
  <joint name="joint5" type="revolute"><parent link="link4"/><child link="link5"/><origin xyz="0 0 0.1" rpy="0 0 0"/><axis xyz="0 1 0"/><limit lower="-1.57079" upper="1.57079" effort="100" velocity="1.0"/></joint>
  <link name="link5">
    <visual><geometry><cylinder radius="0.05" length="0.1"/></geometry><origin xyz="0 0 0.05" rpy="0 0 0"/><material name="blue"/></visual>
    <collision><geometry><cylinder radius="0.05" length="0.1"/></geometry><origin xyz="0 0 0.05" rpy="0 0 0"/></collision>
    <inertial><mass value="0.5"/><inertia ixx="0.01" ixy="0" ixz="0" iyy="0.01" iyz="0" izz="0.01"/></inertial>
  </link>
  <joint name="joint6" type="revolute"><parent link="link5"/><child link="tool0"/><origin xyz="0 0 0.1" rpy="0 0 0"/><axis xyz="1 0 0"/><limit lower="-3.14159" upper="3.14159" effort="100" velocity="1.0"/></joint>
  <link name="tool0">
    <inertial><mass value="0.001"/><inertia ixx="0.0001" ixy="0.0" ixz="0.0" iyy="0.0001" iyz="0.0" izz="0.0001"/></inertial>
  </link>
  
  <joint name="gripper_base_joint" type="fixed"><parent link="tool0"/><child link="gripper_base"/><origin xyz="0 0 0" rpy="0 0 0"/></joint>
  <link name="gripper_base">
      <visual><geometry><box size="0.05 0.1 0.05"/></geometry><material name="grey"/></visual>
      <collision><geometry><box size="0.05 0.1 0.05"/></geometry></collision>
      <inertial><mass value="0.2"/><inertia ixx="0.001" ixy="0" ixz="0" iyy="0.001" iyz="0" izz="0.001"/></inertial>
  </link>
  <joint name="finger_left_joint" type="prismatic"><parent link="gripper_base"/><child link="finger_left_link"/><origin xyz="0 0.05 0" rpy="0 0 0"/><axis xyz="0 1 0"/><limit lower="0.0" upper="0.04" effort="10" velocity="0.1"/></joint>
  <link name="finger_left_link">
      <visual><geometry><box size="0.08 0.01 0.02"/></geometry><origin xyz="0.04 0 0"/><material name="black"/></visual>
      <collision><geometry><box size="0.08 0.01 0.02"/></geometry><origin xyz="0.04 0 0"/></collision>
      <inertial><mass value="0.05"/><inertia ixx="0.0001" ixy="0" ixz="0" iyy="0.0001" iyz="0" izz="0.0001"/></inertial>
  </link>
  <joint name="finger_right_joint" type="prismatic"><parent link="gripper_base"/><child link="finger_right_link"/><origin xyz="0 -0.05 0" rpy="0 0 0"/><axis xyz="0 1 0"/><limit lower="0.0" upper="0.04" effort="10" velocity="0.1"/></joint>
  <link name="finger_right_link">
      <visual><geometry><box size="0.08 0.01 0.02"/></geometry><origin xyz="0.04 0 0"/><material name="black"/></visual>
      <collision><geometry><box size="0.08 0.01 0.02"/></geometry><origin xyz="0.04 0 0"/></collision>
      <inertial><mass value="0.05"/><inertia ixx="0.0001" ixy="0" ixz="0" iyy="0.0001" iyz="0" izz="0.0001"/></inertial>
  </link>

  <joint name="lidar_joint" type="fixed"><parent link="base_link"/><child link="lidar_link"/><origin xyz="0.2 0 0.05" rpy="0 0 0"/></joint>
  <link name="lidar_link">
    <visual><geometry><cylinder radius="0.05" length="0.04"/></geometry><material name="black"/></visual>
    <collision><geometry><cylinder radius="0.05" length="0.04"/></geometry></collision>
    <inertial><mass value="0.1"/><inertia ixx="0.001" ixy="0" ixz="0" iyy="0.001" iyz="0" izz="0.001"/></inertial>
  </link>
  <joint name="camera_joint" type="fixed"><parent link="link5"/><child link="camera_link"/><origin xyz="0 0 0.05" rpy="0 1.57079632679 0"/></joint>
  <link name="camera_link">
    <visual><geometry><box size="0.02 0.08 0.03"/></geometry><material name="black"/></visual>
    <collision><geometry><box size="0.02 0.08 0.03"/></geometry></collision>
    <inertial><mass value="0.05"/><inertia ixx="0.0001" ixy="0" ixz="0" iyy="0.0001" iyz="0" izz="0.0001"/></inertial>
  </link>

  <ros2_control name="FoundryBotSystem" type="system">
    <hardware><plugin>gazebo_ros2_control/GazeboSystem</plugin></hardware>
    <joint name="left_wheel_joint"><command_interface name="velocity"/><state_interface name="position"/><state_interface name="velocity"/></joint>
    <joint name="right_wheel_joint"><command_interface name="velocity"/><state_interface name="position"/><state_interface name="velocity"/></joint>
    <joint name="joint1"><command_interface name="position"/><state_interface name="position"/><state_interface name="velocity"/></joint>
    <joint name="joint2"><command_interface name="position"/><state_interface name="position"/><state_interface name="velocity"/></joint>
    <joint name="joint3"><command_interface name="position"/><state_interface name="position"/><state_interface name="velocity"/></joint>
    <joint name="joint4"><command_interface name="position"/><state_interface name="position"/><state_interface name="velocity"/></joint>
    <joint name="joint5"><command_interface name="position"/><state_interface name="position"/><state_interface name="velocity"/></joint>
    <joint name="joint6"><command_interface name="position"/><state_interface name="position"/><state_interface name="velocity"/></joint>
    <joint name="finger_left_joint"><command_interface name="position"/><state_interface name="position"/><state_interface name="velocity"/></joint>
    <joint name="finger_right_joint"><command_interface name="position"/><state_interface name="position"/><state_interface name="velocity"/></joint>
  </ros2_control>
  <gazebo>
    <plugin filename="libgazebo_ros2_control.so" name="gazebo_ros2_control">
        <robot_sim_type>gazebo_ros2_control/DefaultRobotHWSim</robot_sim_type>
        <parameters>$(find ros2_foundry_description)/config/ros2_controllers.yaml</parameters>
    </plugin>
  </gazebo>
</robot>